<?xml version="1.0" ?>
<robot name="day" xmlns:xacro="http://www.ros.org/wiki/xacro">

<xacro:include filename="$(find day_description)/urdf/materials.xacro" />
<xacro:include filename="$(find day_description)/urdf/day.trans" />
<xacro:include filename="$(find day_description)/urdf/day.gazebo" />
<link name="base_link">
  <inertial>
    <origin xyz="0.015520402986513018 -0.05512178270793456 -0.11439824747765832" rpy="0 0 0"/>
    <mass value="2.3724092855579104"/>
    <inertia ixx="0.003131" iyy="0.009101" izz="0.00928" ixy="-0.000285" iyz="0.0" ixz="-5e-06"/>
  </inertial>
  <visual>
    <origin xyz="0 0 0" rpy="0 0 0"/>
    <geometry>
      <mesh filename="package://day_description/meshes/base_link.stl" scale="0.001 0.001 0.001"/>
    </geometry>
    <material name="silver"/>
  </visual>
  <collision>
    <origin xyz="0 0 0" rpy="0 0 0"/>
    <geometry>
      <mesh filename="package://day_description/meshes/base_link.stl" scale="0.001 0.001 0.001"/>
    </geometry>
  </collision>
</link>

<link name="left_wheel_1">
  <inertial>
    <origin xyz="1.56284390623318e-07 -1.576413828988099e-07 -0.00500037335205003" rpy="0 0 0"/>
    <mass value="0.6165375582669969"/>
    <inertia ixx="0.00039" iyy="0.00039" izz="0.000771" ixy="0.0" iyz="0.0" ixz="0.0"/>
  </inertial>
  <visual>
    <origin xyz="0.08087 0.052226 0.169362" rpy="0 0 0"/>
    <geometry>
      <mesh filename="package://day_description/meshes/left_wheel_1.stl" scale="0.001 0.001 0.001"/>
    </geometry>
    <material name="silver"/>
  </visual>
  <collision>
    <origin xyz="0.08087 0.052226 0.169362" rpy="0 0 0"/>
    <geometry>
      <mesh filename="package://day_description/meshes/left_wheel_1.stl" scale="0.001 0.001 0.001"/>
    </geometry>
  </collision>
</link>

<link name="right_wheel_1">
  <inertial>
    <origin xyz="3.992455807622086e-08 -4.870916867141806e-07 -0.0050003733520504745" rpy="0 0 0"/>
    <mass value="0.6165375582669969"/>
    <inertia ixx="0.00039" iyy="0.00039" izz="0.000771" ixy="0.0" iyz="0.0" ixz="0.0"/>
  </inertial>
  <visual>
    <origin xyz="0.080335 0.051902 0.059362" rpy="0 0 0"/>
    <geometry>
      <mesh filename="package://day_description/meshes/right_wheel_1.stl" scale="0.001 0.001 0.001"/>
    </geometry>
    <material name="silver"/>
  </visual>
  <collision>
    <origin xyz="0.080335 0.051902 0.059362" rpy="0 0 0"/>
    <geometry>
      <mesh filename="package://day_description/meshes/right_wheel_1.stl" scale="0.001 0.001 0.001"/>
    </geometry>
  </collision>
</link>

<joint name="Rev1" type="continuous">
  <origin xyz="-0.08087 -0.052226 -0.169362" rpy="0 0 0"/>
  <parent link="base_link"/>
  <child link="left_wheel_1"/>
  <axis xyz="-0.0 -0.0 -1.0"/>
</joint>

<joint name="Rev2" type="continuous">
  <origin xyz="-0.080335 -0.051902 -0.059362" rpy="0 0 0"/>
  <parent link="base_link"/>
  <child link="right_wheel_1"/>
  <axis xyz="0.0 0.0 1.0"/>
</joint>

</robot>
